Workbook

Sheet Summary
A1: Task 8: Data Quality Rules ( aligned with the KPIs Document)
A2: Week 1 | Source: Data_Final_project IR.xlsx | Counts are pre-cleaning
A4: General rules (binding for the whole team)
A5: 1. A blank stays NULL and is never converted to zero; a true zero differs from a blank.
A6: 2. No outlier is deleted just because it is large: it is checked, flagged and its effect explained.
A7: 3. Text is never converted to a date by guessing; status text ("Pre-PQ Process", "Date Not Captured") stays a status and its date is NULL.
A8: 4. No duplicate is removed before its duplicate key and reason are defined (see Scope_Rules B).
A9: 5. Raw values are always kept; handling happens in new columns / the Working layer, and every change is logged with the number of rows affected.
A10: 6. No one uses a missing or wrong field in a KPI without a documented decision in this file.
A12: Decision summary (calculated from the rule sheets)
A13: Decision | B13: Shipments layer (37 columns) | C13: Hospital layer (64 columns) | D13: Total dataset columns (101)
A14: KPI | B14: =COUNTIF(Shipments_Rules!$I$5:$I$41,A14) -> 9 | C14: =COUNTIF(Hospital_Rules!$K$5:$K$68,A14) -> 14 | D14: =B14+C14 -> 23
A15: Flag | B15: =COUNTIF(Shipments_Rules!$I$5:$I$41,A15) -> 5 | C15: =COUNTIF(Hospital_Rules!$K$5:$K$68,A15) -> 11 | D15: =B15+C15 -> 16
A16: Dimension | B16: =COUNTIF(Shipments_Rules!$I$5:$I$41,A16) -> 9 | C16: =COUNTIF(Hospital_Rules!$K$5:$K$68,A16) -> 8 | D16: =B16+C16 -> 17
A17: Key | B17: =COUNTIF(Shipments_Rules!$I$5:$I$41,A17) -> 4 | C17: =COUNTIF(Hospital_Rules!$K$5:$K$68,A17) -> 14 | D17: =B17+C17 -> 18
A18: Not in KPI | B18: =COUNTIF(Shipments_Rules!$I$5:$I$41,A18) -> 10 | C18: =COUNTIF(Hospital_Rules!$K$5:$K$68,A18) -> 17 | D18: =B18+C18 -> 27
A19: Total classified columns | B19: =SUM(B14:B18) -> 37 | C19: =SUM(C14:C18) -> 64 | D19: =SUM(D14:D18) -> 101
A21: Approved team decisions
A22: Decision needed | B22: Proposal | C22: Owner | D22: Status
A23: Does "Partially Received" count as received for PO On-Time Rate? | B23: Yes. Received and Partially Received count as received only when received_date is valid. Rejected orders are excluded from the on-time denominator and reported separately. | C23: Hossam + Ola | D23: Approved
A24: Rows outside 1 Jan - 31 Mar 2026 | B24: Flag Out_of_Period. Exclude strictly from time-sensitive KPIs (e.g., daily Stockout Rate); retain in Raw and Staging layers without deletion. | C24: Team | D24: Approved
A25: Conflicting duplicate po_id (5 groups, differ only in qty_ordered) | B25: Keep the first occurrence per po_id. Log the qty_ordered discrepancy in the Duplicate Log. All date fields are identical, so PO Delay and On-Time Rate are unaffected; do not guess a quantity. | C25: Yahia + Hossam | D25: Approved
A26: Fully identical duplicate rows | B26: Remove extra copies of fully identical rows from the Clean Working Layer only after logging all duplicates in the Duplicate Log. | C26: Yahia + Hossam | D26: Approved
A27: S09 (RDC) in supplier rankings | B27: Separate S09 as an internal Regional Distribution Center / Warehouse; exclude it from commercial supplier rankings. | C27: Ola | D27: Approved
A29: Settled by the KPIs Document
A30: "Not given - transferred" is NOT shortage-type. Shortage-type = "Delayed - stock unavailable", "Substitute used", "Not given" (exact match).

Sheet Shipments_Rules
A1: Data Quality Rules: Shipments table (sheet "in")
A2: Counts are computed directly from the source file before any cleaning. Decision tags: KPI = enters a KPI calculation | Flag = kept with a quality flag | Dimension = grouping attribute | Key = key/reference | Not in KPI = kept, not used in any KPI.
A4: # | B4: Column | C4: Rows | D4: Null | E4: % Null | F4: Text instead of number/date | G4: Distinct raw | H4: Observed issue | I4: Decision | J4: Rule / handling | K4: Serves
A5: 1 | B5: id | C5: 46 | D5: 0 | E5: =D5/C5 -> 0.0% | G5: 46 | H5: Unique key; no duplicates. | I5: Key | J5: Row key (grain = one shipment line). Test: COUNT(*) = COUNT(DISTINCT id). Exclusion policy for Total Shipments: none, all rows are kept; invalid values are handled inside each KPI denominator. | K5: Total Shipments
A6: 2 | B6: project code | C6: 46 | D6: 0 | E6: =D6/C6 -> 0.0% | G6: 12 | H6: Operational reference (12 values); used only in duplicate checks. | I6: Key | J6: Kept as reference; no KPI. | K6: PK09
A7: 3 | B7: pq # | C7: 46 | D7: 0 | E7: =D7/C7 -> 0.0% | G7: 18 | H7: Contains status text such as "Pre-PQ Process". | I7: Not in KPI | J7: Kept as-is. | K7: n/a
A8: 4 | B8: po / so # | C8: 46 | D8: 0 | E8: =D8/C8 -> 0.0% | G8: 40 | H8: Repeated values do NOT mean duplicate shipments (one order can have several lines). | I8: Key | J8: Reference only; no row is removed because of it. | K8: PK09
A9: 5 | B9: asn/dn # | C9: 46 | D9: 0 | E9: =D9/C9 -> 0.0% | G9: 40 | H9: Same as po / so #. | I9: Key | J9: Reference only. | K9: PK09
A10: 6 | B10: country | C10: 46 | D10: 0 | E10: =D10/C10 -> 0.0% | G10: 7 | H10: Encoding error in 6 rows (CÃ´te d'Ivoire). | I10: Dimension | J10: New column country_clean via a documented mapping; raw value kept; no guessing. | K10: Q03, Q06, Q14
A11: 7 | B11: managed by | C11: 46 | D11: 0 | E11: =D11/C11 -> 0.0% | G11: 1 | H11: Single value (PMO - US): no variation. | I11: Not in KPI | J11: Not usable for analysis; kept. | K11: n/a
A12: 8 | B12: fulfill via | C12: 46 | D12: 0 | E12: =D12/C12 -> 0.0% | G12: 1 | H12: Single value (Direct Drop) in all rows; no "From RDC". | I12: Not in KPI | J12: No comparison between fulfillment routes is possible (one group). | K12: Q10, Task 32
A13: 9 | B13: vendor inco term | C13: 46 | D13: 0 | E13: =D13/C13 -> 0.0% | G13: 3 | H13: 3 values; no visible issues. | I13: Dimension | J13: Trim/case standardization only. | K13: Q03, Q10, Q11
A14: 10 | B14: shipment mode | C14: 46 | D14: 1 | E14: =D14/C14 -> 2.2% | G14: 1 | H14: 1 blank; all others are "Air" (single value). | I14: Flag | J14: Blank stays NULL + flag (Missing Mode); it is not a mode. Mode comparison is impossible (one mode). | K14: Q04, Q05, Q12
A15: 11 | B15: pq first sent to client date | C15: 46 | D15: 0 | E15: =D15/C15 -> 0.0% | F15: 21 | G15: 18 | H15: 21 rows hold the text "Pre-PQ Process" instead of a date. | I15: Flag | J15: Derived date column (text -> NULL) + status column for the text; text is never converted to a date. | K15: n/a
A16: 12 | B16: po sent to vendor date | C16: 46 | D16: 0 | E16: =D16/C16 -> 0.0% | F16: 1 | G16: 31 | H16: 1 row holds the text "Date Not Captured". | I16: KPI | J16: Feeds Lead Time on valid rows only; text -> NULL + flag; no date is inferred. | K16: Q08, Q09
A17: 13 | B17: scheduled delivery date | C17: 46 | D17: 0 | E17: =D17/C17 -> 0.0% | F17: 0 | G17: 39 | H17: All values are valid dates. | I17: KPI | J17: Feeds Delay Days. | K17: Q01, Q02
A18: 14 | B18: delivered to client date | C18: 46 | D18: 0 | E18: =D18/C18 -> 0.0% | F18: 0 | G18: 39 | H18: All values are valid dates; defines the time axis. | I18: KPI | J18: Feeds Delay Days and the Q02 calendar. | K18: Q01, Q02
A19: 15 | B19: delivery recorded date | C19: 46 | D19: 0 | E19: =D19/C19 -> 0.0% | F19: 0 | G19: 39 | H19: All values are valid dates. | I19: KPI | J19: Feeds Lead Time Days. | K19: Q08
A20: 16 | B20: product group | C20: 46 | D20: 0 | E20: =D20/C20 -> 0.0% | G20: 3 | H20: 3 values. | I20: Dimension | J20: Case standardization only. | K20: Q21+
A21: 17 | B21: sub classification | C21: 46 | D21: 0 | E21: =D21/C21 -> 0.0% | G21: 2 | H21: 2 values. | I21: Dimension | J21: Case standardization only. | K21: Q03, Q10, Q11
A22: 18 | B22: vendor | C22: 46 | D22: 0 | E22: =D22/C22 -> 0.0% | G22: 11 | H22: 11 vendors; IDA FOUNDATION has 17 lines, most others 1-7. No RDC (fulfill via is a single value). | I22: Dimension | J22: Standardize names. Any vendor ranking needs a minimum sample size. | K22: Q03, Q10, Q11
A23: 19 | B23: item description | C23: 46 | D23: 0 | E23: =D23/C23 -> 0.0% | G23: 17 | H23: 17 values. | I23: Dimension | J23: Kept. | K23: n/a
A24: 20 | B24: molecule/test type | C24: 46 | D24: 0 | E24: =D24/C24 -> 0.0% | G24: 13 | H24: 13 values. | I24: Dimension | J24: Kept. | K24: n/a
A25: 21 | B25: brand | C25: 46 | D25: 0 | E25: =D25/C25 -> 0.0% | G25: 4 | H25: 4 values. | I25: Dimension | J25: Kept. | K25: n/a
A26: 22 | B26: dosage | C26: 46 | D26: 8 | E26: =D26/C26 -> 17.4% | G26: 8 | H26: 8 blanks (genuinely missing). | I26: Flag | J26: Stays NULL + flag; never filled; not used in any KPI. | K26: n/a
A27: 23 | B27: dosage form | C27: 46 | D27: 0 | E27: =D27/C27 -> 0.0% | G27: 7 | H27: 7 values. | I27: Dimension | J27: Kept. | K27: n/a
A28: 24 | B28: unit of measure (per pack) | C28: 46 | D28: 0 | E28: =D28/C28 -> 0.0% | F28: 0 | G28: 9 | H28: Numeric, no issues. | I28: Not in KPI | J28: Kept (reference for quantity conversion). | K28: n/a
A29: 25 | B29: line item quantity | C29: 46 | D29: 0 | E29: =D29/C29 -> 0.0% | F29: 0 | G29: 36 | H29: Numeric; no blanks, zeros or negatives. | I29: KPI | J29: Feeds Total Quantity; reconciliation total (PK04). | K29: Q01, PK04
A30: 26 | B30: line item value | C30: 46 | D30: 0 | E30: =D30/C30 -> 0.0% | F30: 0 | G30: 41 | H30: Numeric; no blanks, zeros or negatives. | I30: KPI | J30: Feeds Shipment Value USD and the Freight/Value denominator; reconciliation total (PK04). | K30: Q02, Q09, Q11, Q12
A31: 27 | B31: pack price | C31: 46 | D31: 0 | E31: =D31/C31 -> 0.0% | F31: 0 | G31: 35 | H31: Numeric. | I31: Flag | J31: Outlier review only (IQR/P90); nothing is deleted. | K31: Tasks 23/26
A32: 28 | B32: unit price | C32: 46 | D32: 0 | E32: =D32/C32 -> 0.0% | F32: 0 | G32: 15 | H32: Numeric. | I32: Flag | J32: Outlier review only; nothing is deleted. | K32: Tasks 23/26
A33: 29 | B33: manufacturing site | C33: 46 | D33: 0 | E33: =D33/C33 -> 0.0% | G33: 18 | H33: 18 values. | I33: Not in KPI | J33: Outside the questions. | K33: n/a
A34: 30 | B34: first line designation | C34: 46 | D34: 0 | E34: =D34/C34 -> 0.0% | G34: 2 | H34: Boolean. | I34: Not in KPI | J34: Outside the questions. | K34: n/a
A35: 31 | B35: weight (kilograms) | C35: 46 | D35: 0 | E35: =D35/C35 -> 0.0% | F35: 8 | G35: 41 | H35: 8 rows hold text instead of a number (6 "See ASN" + 2 "Weight Captured Separately"). No zero or negative weights. | I35: KPI | J35: Numeric column Weight_Kg_Num (text -> NULL) + status column keeping the text; no replacement by zero. Rows with NULL weight are excluded from Freight per Kg and their count is shown. | K35: Q13, Freight per Kg
A36: 32 | B36: freight cost (usd) | C36: 46 | D36: 0 | E36: =D36/C36 -> 0.0% | F36: 8 | G36: 43 | H36: 8 rows hold text instead of a number (6 "See ASN" + 2 "Freight Included in Commodity Cost"). No zero or negative values. | I36: KPI | J36: Numeric column Freight_Cost_Num + status; text -> NULL. Freight/Value = SUM(Freight) / SUM(Value) over the SAME rows where freight is numeric (numerator and denominator on one row set). | K36: Q12, Q13, Q14
A37: 33 | B37: line item insurance (usd) | C37: 46 | D37: 0 | E37: =D37/C37 -> 0.0% | F37: 0 | G37: 41 | H37: No blanks in this sample; 0 zero values. | I37: KPI | J37: Feeds Insurance/Value; a true zero is kept distinct from a missing value; reconciliation total (PK04). | K37: Insurance/Value, PK04
A38: 34 | B38: batch_number | C38: 46 | D38: 3 | E38: =D38/C38 -> 6.5% | G38: 42 | H38: Extra column vs the original data; 3 blanks. | I38: Not in KPI | J38: Out of scope (Task 12). | K38: n/a
A39: 35 | B39: expiry_date | C39: 46 | D39: 2 | E39: =D39/C39 -> 4.3% | F39: 1 | G39: 44 | H39: Extra column; 2 blanks. | I39: Not in KPI | J39: Out of scope (Task 12). | K39: n/a
A40: 36 | B40: customs_clearance_days | C40: 46 | D40: 1 | E40: =D40/C40 -> 2.2% | F40: 2 | G40: 11 | H40: Extra column; 1 blank and 2 texts such as "3 days" and "~6". | I40: Not in KPI | J40: Out of scope (Task 12). | K40: n/a
A41: 37 | B41: receiving_inspection_result | C41: 46 | D41: 6 | E41: =D41/C41 -> 13.0% | G41: 8 | H41: Extra column; 6 blanks. | I41: Not in KPI | J41: Out of scope (Task 12). | K41: n/a
...

Sheet Hospital_Rules
A1: Data Quality Rules: Hospital layer (inventory_daily, purchase_orders, patient_cases + reference tables)
A2: Hospital layer is described in the data file as synthetic/illustrative. Counts are pre-cleaning. A negative count is not always an error (e.g. negative stock_adjustment_qty is a legitimate adjustment).
A4: # | B4: Table | C4: Column | D4: Rows | E4: Null | F4: % Null | G4: Text instead of number/date | H4: Negative | I4: Distinct raw | J4: Observed issue | K4: Decision | L4: Rule / handling | M4: Serves
A5: 1 | B5: inventory_daily | C5: record_id | D5: 10793 | E5: 0 | F5: =E5/D5 -> 0.0% | I5: 10631 | J5: 162 excess duplicates on record_id (162 rows are fully identical to another row; 0 conflicting groups). | K5: Key | L5: Fully identical rows are removed from the clean copy only, after being logged. See Scope_Rules for the full duplicate policy. | M5: All inventory KPIs
A6: 2 | B6: inventory_daily | C6: date | D6: 10793 | E6: 0 | F6: =E6/D6 -> 0.0% | G6: 0 | I6: 314 | J6: Mixed formats: ISO 10,225, dd/mm/yyyy 417, dd-Mon-yy 108, Excel serial 43. Slash dates: 417 values, 231 have day > 12 and 0 have month > 12, so the format is confirmed as dd/mm/yyyy. 43 rows fall outside 1 Jan - 31 Mar 2026. | K6: Flag | L6: Standardize to one date type; parse every slash date explicitly with format='%d/%m/%Y' (dd/mm/yyyy), never locale/default parsing. Out-of-period rows get an Out_of_Period flag and are not deleted; exclude only from time-sensitive KPIs. | M6: Q17
A7: 3 | B7: inventory_daily | C7: hospital_id | D7: 10793 | E7: 0 | F7: =E7/D7 -> 0.0% | I7: 17 | J7: 17 raw spellings (H_A, h-a, "H-A " ...). After standardization: ['H-A', 'H-B', 'H-C', 'H-D', 'H-E']. 23 rows carry H-E, which is not in the hospitals table. | K7: Key | L7: trim + upper + replace _ with -; H-E is flagged Orphan and never merged by guessing. | M7: Q17
A8: 4 | B8: inventory_daily | C8: item_id | D8: 10793 | E8: 0 | F8: =E8/D8 -> 0.0% | I8: 93 | J8: 93 raw spellings, 33 after trim + upper. 35 rows have codes outside I001-I030 (e.g. I3O1, I099). | K8: Key | L8: trim + upper; invalid codes get Invalid_Item and are not corrected by guessing (I3O1 is not auto-mapped to I301). | M8: Q17, Q18
A9: 5 | B9: inventory_daily | C9: opening_stock | D9: 10793 | E9: 0 | F9: =E9/D9 -> 0.0% | G9: 0 | H9: 0 | I9: 1057 | J9: Numeric; no blanks or negatives. | K9: Not in KPI | L9: Kept. | M9: n/a
A10: 6 | B10: inventory_daily | C10: received_qty | D10: 10793 | E10: 99 | F10: =E10/D10 -> 0.9% | G10: 0 | H10: 43 | I10: 320 | J10: Blanks + negative values (a negative receipt is illogical). | K10: Flag | L10: Negatives are flagged Negative_Received; not corrected without evidence. | M10: Q17, Q18
A11: 7 | B11: inventory_daily | C11: requested_qty | D11: 10793 | E11: 99 | F11: =E11/D11 -> 0.9% | G11: 0 | H11: 0 | I11: 383 | J11: Blanks. | K11: KPI | L11: NULL stays NULL; used in request/dispensed/unmet consistency. | M11: Q17, Q18
A12: 8 | B12: inventory_daily | C12: dispensed_qty | D12: 10793 | E12: 348 | F12: =E12/D12 -> 3.2% | G12: 0 | H12: 0 | I12: 375 | J12: Blanks. | K12: KPI | L12: NULL stays NULL; used in request/dispensed/unmet consistency. | M12: Q17, Q18
A13: 9 | B13: inventory_daily | C13: unmet_demand_qty | D13: 10793 | E13: 1678 | F13: =E13/D13 -> 15.5% | G13: 0 | H13: 0 | I13: 188 | J13: 1,678 blank rows. Blank share by hospital after standardization: H-A 3%, H-B 2%, H-C 56%, H-D 3% (not random; concentrated in one hospital). 18 of 8,742 rows: requested != dispensed + unmet. | K13: KPI | L13: Blank stays NULL (not 0). Excluded from the Stockout Rate denominator and the exclusion count is reported; never filled with an average. Inconsistent rows are flagged. | M13: Q17, Q18, Stockout Rate
A14: 10 | B14: inventory_daily | C14: expired_writeoff_qty | D14: 10793 | E14: 0 | F14: =E14/D14 -> 0.0% | G14: 0 | H14: 0 | I14: 49 | J14: Numeric. | K14: Not in KPI | L14: Kept. | M14: n/a
A15: 11 | B15: inventory_daily | C15: damaged_lost_qty | D15: 10793 | E15: 0 | F15: =E15/D15 -> 0.0% | G15: 0 | H15: 0 | I15: 33 | J15: Numeric. | K15: Not in KPI | L15: Kept. | M15: n/a
A16: 12 | B16: inventory_daily | C16: stock_adjustment_qty | D16: 10793 | E16: 0 | F16: =E16/D16 -> 0.0% | G16: 0 | H16: 2308 | I16: 70 | J16: Many negatives; these are legitimate adjustments, not errors. | K16: Not in KPI | L16: Negatives are not modified. | M16: n/a
A17: 13 | B17: inventory_daily | C17: closing_stock | D17: 10793 | E17: 154 | F17: =E17/D17 -> 1.4% | G17: 43 | H17: 46 | I17: 1067 | J17: Blanks + text (-, ?, thousands separators such as 1,306) + negatives. | K17: Flag | L17: Not a headline KPI; numeric conversion only by a documented rule (remove thousands separator), the rest NULL + flag. | M17: Q17, Q18
A18: 14 | B18: inventory_daily | C18: stock_value_egp | D18: 10793 | E18: 236 | F18: =E18/D18 -> 2.2% | G18: 86 | H18: 0 | I18: 3206 | J18: Blanks + text like "EGP 6,754.00". | K18: Not in KPI | L18: Not used by KPIs; if needed: strip prefix and separator by a documented rule. | M18: n/a
A19: 15 | B19: inventory_daily | C19: avg_daily_dispensed_7d | D19: 10793 | E19: 244 | F19: =E19/D19 -> 2.3% | G19: 0 | H19: 0 | I19: 1378 | J19: Blanks. | K19: Not in KPI | L19: Kept. | M19: n/a
A20: 16 | B20: inventory_daily | C20: days_of_cover | D20: 10793 | E20: 624 | F20: =E20/D20 -> 5.8% | G20: 92 | H20: 0 | I20: 544 | J20: Blanks + text with decimal comma (e.g. 4,3). | K20: Not in KPI | L20: Not used by the 22 questions; converted only if a KPI is added. | M20: n/a
... A23: 19 | B23: inventory_daily | C23: reorder_point | D23: 10793 | E23: 255 | F23: =E23/D23 -> 2.4% | G23: 0 | H23: 0 | I23: 81 | J23: Blanks. | K23: Not in KPI | L23: Kept. | M23: n/a
A24: 20 | B24: inventory_daily | C24: stockout_flag | D24: 10793 | E24: 0 | F24: =E24/D24 -> 0.0% | I24: 6 | J24: 6 formats (0: 8,970, 1: 1,620, Y: 65, FALSE: 48, TRUE: 46, N: 44). | K24: Flag | L24: NOT used as a source. Stockout is recomputed as (unmet_demand_qty > 0) per the KPI Document and compared; any difference is documented. | M24: Q17
A25: 21 | B25: purchase_orders | C25: po_id | D25: 2187 | E25: 0 | F25: =E25/D25 -> 0.0% | I25: 2163 | J25: 24 excess duplicates (19 fully identical rows; 5 conflicting groups differing only in qty_ordered). | K25: Key | L25: See Scope_Rules duplicate policy: identical rows removed after logging; conflicting groups keep the first occurrence and log the quantity conflict. | M25: Q15, Q16
A26: 22 | B26: purchase_orders | C26: order_date | D26: 2187 | E26: 0 | F26: =E26/D26 -> 0.0% | G26: 0 | I26: 160 | J26: Mixed formats: ISO 2,095, dd/mm/yyyy 61, dd-Mon-yy 23, Excel serial 8; 4 rows outside the period (e.g. 2025/2027). | K26: Flag | L26: Parse slash dates explicitly with format='%d/%m/%Y' (dd/mm/yyyy), then standardize to one date type; out-of-period rows are flagged, not deleted. | M26: Q15, Q16
A27: 23 | B27: purchase_orders | C27: hospital_id | D27: 2187 | E27: 0 | F27: =E27/D27 -> 0.0% | I27: 17 | J27: 17 raw spellings; 4 rows with a code outside H-A..H-D. | K27: Key | L27: Same standardization rule. | M27: Q15-Q17
A28: 24 | B28: purchase_orders | C28: item_id | D28: 2187 | E28: 0 | F28: =E28/D28 -> 0.0% | I28: 32 | J28: 32 raw values; 8 rows outside I001-I030. | K28: Key | L28: trim + upper; invalid codes get Invalid_Item. | M28: Q15, Q18
A29: 25 | B29: purchase_orders | C29: supplier_id | D29: 2187 | E29: 0 | F29: =E29/D29 -> 0.0% | I29: 9 | J29: 9 values: S01-S08 plus S09 (SCMS regional distribution center) in 1 row. | K29: Key | L29: S09 is a regional warehouse, not a real supplier: flagged and kept out of supplier rankings. | M29: Q15
A30: 26 | B30: purchase_orders | C30: supplier_name_raw | D30: 2187 | E30: 0 | F30: =E30/D30 -> 0.0% | I30: 25 | J30: 25 raw name spellings for the suppliers. | K30: Not in KPI | L30: Analysis uses supplier_id; the raw name is for review only (Task 29: verify each spelling maps to exactly one supplier_id). | M30: Q15
A31: 27 | B31: purchase_orders | C31: qty_ordered | D31: 2187 | E31: 0 | F31: =E31/D31 -> 0.0% | G31: 0 | H31: 7 | I31: 245 | J31: Negative values (a negative order quantity is illogical). | K31: Flag | L31: Flagged, not corrected without evidence. | M31: Q15, Q16
A32: 28 | B32: purchase_orders | C32: expected_delivery_date | D32: 2187 | E32: 0 | F32: =E32/D32 -> 0.0% | G32: 0 | I32: 96 | J32: All values are valid ISO dates. | K32: KPI | L32: Feeds PO Delay Days and PO On-Time Rate. | M32: Q15, Q16
A33: 29 | B33: purchase_orders | C33: received_date | D33: 2187 | E33: 194 | F33: =E33/D33 -> 8.9% | G33: 0 | I33: 88 | J33: Blank for unreceived orders (expected for In Transit). But 25 Received/Partially Received rows have NO date and 1 In Transit row HAS a date (raw rows). | K33: KPI | L33: Blank stays NULL. A PO delay is computed only for "valid received POs" as defined in Scope_Rules. Status/date conflicts are flagged Status_Date_Conflict and excluded from the denominator with the count reported. | M33: Q15, Q16
A34: 30 | B34: purchase_orders | C34: qty_received | D34: 2187 | E34: 179 | F34: =E34/D34 -> 8.2% | G34: 15 | H34: 0 | I34: 316 | J34: Blanks + text. | K34: Flag | L34: NULL + flag; never filled. | M34: Q15, Q16
A35: 31 | B35: purchase_orders | C35: unit_cost_egp | D35: 2187 | E35: 0 | F35: =E35/D35 -> 0.0% | G35: 62 | H35: 0 | I35: 1661 | J35: 23 rows in "$..." format (dollar sign inside an EGP column) plus other text. | K35: Flag | L35: No currency conversion by guessing; flagged Currency_Mismatch. Note: Unmet Demand EGP uses items.unit_cost_egp, not this column. | M35: Q18 (indirect)
A36: 32 | B36: purchase_orders | C36: po_status | D36: 2187 | E36: 0 | F36: =E36/D36 -> 0.0% | I36: 14 | J36: 14 raw spellings standardize to 4 statuses: Received 1,758, Partially Received 251, In Transit 170, Rejected 8. | K36: KPI | L36: trim + case standardization; before/after counts report; meaning unchanged. Defines "received" (see Scope_Rules). | M36: Q15, Q16
A37: 33 | B37: patient_cases | C37: case_id | D37: 5665 | E37: 0 | F37: =E37/D37 -> 0.0% | I37: 5598 | J37: 67 excess duplicates (67 fully identical rows; 0 conflicting groups). | K37: Key | L37: Same duplicate policy. | M37: Q19-Q21
A38: 34 | B38: patient_cases | C38: hospital_id | D38: 5665 | E38: 0 | F38: =E38/D38 -> 0.0% | I38: 17 | J38: 17 raw spellings; 10 rows outside H-A..H-D. | K38: Key | L38: Same standardization rule. | M38: Q21
A39: 35 | B39: patient_cases | C39: admission_date | D39: 5665 | E39: 0 | F39: =E39/D39 -> 0.0% | G39: 0 | I39: 222 | J39: Mixed formats: ISO 5,379, dd/mm/yyyy 223, dd-Mon-yy 50, Excel serial 13; 4 rows outside the period. | K39: Flag | L39: Parse slash dates explicitly with format='%d/%m/%Y' (dd/mm/yyyy), then standardize to one date type; out-of-period rows are flagged. | M39: Q19, Q20, Q21
A40: 36 | B40: patient_cases | C40: age_years | D40: 5665 | E40: 207 | F40: =E40/D40 -> 3.7% | G40: 44 | H40: 5 | I40: 119 | J40: Blanks + text + negative ages. | K40: Not in KPI | L40: Not used by questions; negatives flagged. | M40: n/a
A41: 37 | B41: patient_cases | C41: gender | D41: 5665 | E41: 133 | F41: =E41/D41 -> 2.3% | I41: 8 | J41: 8 spellings + blanks. | K41: Not in KPI | L41: Not used by questions; standardize only if an analysis is added. | M41: n/a
A42: 38 | B42: patient_cases | C42: diagnosis | D42: 5665 | E42: 0 | F42: =E42/D42 -> 0.0% | I42: 33 | J42: 33 raw values that differ in spelling: needs a mapping. | K42: Dimension | L42: Documented mapping table; two different diseases are never merged on visual similarity (review in Task 27). | M42: Q21
A43: 39 | B43: patient_cases | C43: severity | D43: 5665 | E43: 247 | F43: =E43/D43 -> 4.4% | I43: 6 | J43: Text values (Low/Moderate/High) plus 107 numeric rows (1/2/3) + 247 blanks. | K43: Dimension | L43: 1/2/3 -> Low/Moderate/High per the plan; blanks stay NULL. | M43: Q20, Q21
...

Sheet Scope_Rules
A1: Scope, duplicate policy, "received PO" rule and valid-row definitions
A3: A. Scope: approved in the plan vs found in the data
A4: Dimension | B4: Approved scope | C4: Found in the data (raw) | D4: Impact / decision
A5: Items | B5: I001-I030 (30 items) | C5: inventory: 93 raw spellings -> 33 after standardization; rows with a code outside scope: inventory 35 / PO 8 / cases 22 | D5: Flag Invalid_Item; never corrected by guessing
A6: Suppliers | B6: S01-S08 (8 suppliers) | C6: suppliers table includes S09 (RDC); it appears in 1 PO row | D6: S09 is an internal Regional Distribution Center / Warehouse; exclude from commercial supplier rankings.
A7: Hospitals | B7: H-A to H-D (4) | C7: 17 raw spellings of the 4 + H-E; rows with an invalid code: inventory 23 / PO 4 / cases 10 | D7: Standardize spellings; flag H-E as Orphan
A8: Period | B8: 1 Jan - 31 Mar 2026 | C8: inventory 2025-01-06 to 2027-03-30 (43 outside) | PO 2025-01-31 to 2027-03-05 (4 outside) | cases 2026-01-01 to 2027-02-09 (4 outside) | D8: Flag Out_of_Period; exclude strictly from time-sensitive KPIs only; retain all rows in Raw and Staging without deletion. Decision approved.
A9: Slash-date format | B9: dd/mm/yyyy | C9: inventory: 231 of 417 slash dates have day > 12; none has month > 12 | D9: dd/mm/yyyy confirmed; no ambiguity
A10: Date parsing enforcement | B10: All slash dates (dd/mm/yyyy) | C10: Slash-formatted date values across the datasets | D10: Parse explicitly with format='%d/%m/%Y'; do not use locale/default date parsing or infer mm/dd/yyyy. Apply consistently in staging/cleaning.
A12: B. Duplicate policy (supports PK09: duplicate rate after cleaning = remaining duplicate keys / total rows, target 0%)
A13: Table | B13: Key | C13: Excess duplicate rows | D13: Fully identical rows | E13: Conflicting groups | F13: Rule
A14: inventory_daily | B14: record_id | C14: 162 | D14: 162 | E14: 0 | F14: All duplicates are fully identical: remove the extra copies from the clean table after logging.
A15: purchase_orders | B15: po_id | C15: 24 | D15: Fully identical rows: remove extra copies from the Clean Working Layer after logging. Conflicting groups differ only in qty_ordered; date fields are identical, so PO Delay / On-Time Rate are unaffected. Keep the first occurrence per po_id and log the quantity discrepancy in the Duplicate Log; never guess quantity. | E15: 5 | F15: Identical rows: remove after logging. Conflicting groups differ only in qty_ordered; all date fields are identical, so PO Delay / On-Time are unaffected. Keep the first occurrence per po_id and log the quantity conflict in the Duplicate Log. No quantity is chosen by guessing.
A16: patient_cases | B16: case_id | C16: 67 | D16: 67 | E16: 0 | F16: All duplicates are fully identical: remove the extra copies from the clean table after logging.
A18: C. Purchase-order status vs received_date (raw rows, before duplicate removal)
A19: po_status (standardized) | B19: With received_date | C19: Without received_date | D19: Handling
A20: Received | B20: 1735 | C20: 23 | D20: With date: eligible. Without date: Status_Date_Conflict, excluded from PO On-Time denominator.
A21: Partially Received | B21: 249 | C21: 2 | D21: Counted as received when received_date is valid; decision approved. Without date: Status_Date_Conflict, excluded from the denominator.
A22: In Transit | B22: 1 | C22: 169 | D22: Unreceived: not late and not on time. A row WITH a date is a Status_Date_Conflict.
A23: Rejected | B23: 8 | C23: 0 | D23: Rejected: excluded from PO On-Time denominator and reported separately.
A25: D. Valid-row definitions used as KPI denominators
A26: KPI | B26: Valid row definition | C26: Valid rows
A27: PO Delay Days / PO On-Time Rate | B27: po_status in {Received, Partially Received} AND received_date valid AND expected_delivery_date valid AND not a duplicate po_id (first occurrence kept); partially received counts as received. | C27: 1962
A28: Stockout Rate / Stockout Day Flag | B28: Not a duplicate record_id AND hospital in H-A..H-D AND item in I001-I030 AND date parseable within 1 Jan–31 Mar 2026 AND unmet_demand_qty not NULL. | C28: 8926
A29: Late Rate (shipments) | B29: scheduled and delivered dates both valid | C29: 46
A30: Lead Time Days | B30: po sent to vendor date and delivery recorded date both valid | C30: 45
A31: Freight per Kg | B31: freight and weight both numeric | C31: 38
A32: Inventory rows after removing duplicate record_id: 10,631.
